Workbook

Sheet Summary
A1: PLA
B2: File | C2: Ultimate Tensile Strength (UTS) [MPa] | D2: Tensile Strain at UTS | E2: Young's Modulus (E) [MPa]
A3: IPA | B3: PLA-IPA-1.csv | C3: 25.596006 | D3: 0.39126864 | E3: 7.2058555
B4: PLA-IPA-2.csv | C4: 24.837893 | D4: 0.30072178 | E4: -3.0063863
B5: PLA-IPA-3.csv | C5: 29.572398 | D5: 0.26922572 | E5: -1.4613056
B6: PLA-IPA-4.csv | C6: 15.493145 | D6: 0.34534554 | E6: 0.76070142
B7: PLA-IPA-5.csv | C7: 27.838994 | D7: 0.25479882 | E7: -1.322359
B8: Average | C8: 24.667687 | D8: 0.3122721 | E8: 0.43530123
B9: Standard Deviation | C9: =STDEV(C3:C7) -> 5.458396 | D9: =STDEV(D3:D7) -> 0.056178028 | E9: =STDEV(E3:E7) -> 4.0149094
B10: Standard Deviation of the Mean | C10: =C9/SQRT(5) -> 2.4410689 | D10: =D9/SQRT(5) -> 0.025123578 | E10: =E9/SQRT(5) -> 1.7955221
A11: Water | B11: PLA-W-1.csv | C11: 45.411305 | D11: 0.20098858 | E11: 4.5377597
B12: PLA-W-2.csv | C12: 44.675865 | D12: 0.20297021 | E12: 3.2246314
B13: PLA-W-3.csv | C13: 44.484308 | D13: 0.2035958 | E13: 1.5994169
B14: PLA-W-4.csv | C14: 45.518514 | D14: 0.22398071 | E14: 3.8742289
B15: PLA-W-5.csv | C15: 40.846179 | D15: 0.25482507 | E15: 1.2565858
B16: Average | C16: 44.187234 | D16: 0.21727207 | E16: 2.8985245
B17: Standard Deviation | C17: =STDEV(C11:C15) -> 1.9209579 | D17: =STDEV(D11:D15) -> 0.022978081 | E17: =STDEV(E11:E15) -> 1.4255771
B18: Standard Deviation of the Mean | C18: =C17/SQRT(5) -> 0.85907848 | D18: =D17/SQRT(5) -> 0.01027611 | E18: =E17/SQRT(5) -> 0.63753746
A19: Acetone | B19: PLA-A-1.csv | C19: 44.100503 | D19: 0.2036395 | E19: 1.5688194
B20: PLA-A-2.csv | C20: 44.634819 | D20: 0.16952756 | E20: 2.6523797
B21: PLA-A-3.csv | C21: 46.24327 | D21: 0.19577428 | E21: 2.6630941
B22: PLA-A-4.csv | C22: 42.440134 | D22: 0.222629 | E22: 2.4323956
B23: PLA-A-5.csv | C23: 45.729882 | D23: 0.21154856 | E23: 4.717521
B24: Average | C24: 44.629722 | D24: 0.20062378 | E24: 2.806842
B25: Standard Deviation | C25: =STDEV(C19:C23) -> 1.4906615 | D25: =STDEV(D19:D23) -> 0.020019789 | E25: =STDEV(E19:E23) -> 1.1584609
B26: Standard Deviation of the Mean | C26: =C25/SQRT(5) -> 0.66664408 | D26: =D25/SQRT(5) -> 0.0089531217 | E26: =E25/SQRT(5) -> 0.51807945
A27: Control | B27: P-run-1.csv | C27: 42.265629 | D27: 0.21146102 | E27: 5.0235977
B28: P-run-2.csv | C28: 44.880236 | D28: 0.21610236 | E28: 2.6513379
B29: P-run-3.csv | C29: 43.312453 | D29: 0.23515315 | E29: 5.1413307
B30: P-run-4.csv | C30: 42.037453 | D30: 0.22069121 | E30: 0.063467362
B31: P-run-5.csv | C31: 41.604544 | D31: 0.19576549 | E31: 5.1625052
B32: Average | C32: 42.820063 | D32: 0.21583465 | E32: 3.6084478
B33: Standard Deviation | C33: =STDEV(C27:C31) -> 1.3118805 | D33: =STDEV(D27:D31) -> 0.014307011 | E33: =STDEV(E27:E31) -> 2.2500233
B34: Standard Deviation of the Mean | C34: =C33/SQRT(5) -> 0.58669081 | D34: =D33/SQRT(5) -> 0.0063982897 | E34: =E33/SQRT(5) -> 1.006241
A36: Grey Resin V4
B37: File | C37: Ultimate Tensile Strength (UTS) [MPa] | D37: Tensile Strain at UTS | E37: Young's Modulus (E) [MPa]
A38: IPA | B38: Resin_IPA_1.csv | C38: 34.372697 | D38: 0.2902231 | E38: 5.0324165
B39: Resin_IPA_2.csv | C39: 36.163027 | D39: 0.36764213 | E39: 4.642463
B40: Resin_IPA_3.csv | C40: 34.168396 | D40: 0.31976811 | E40: 2.9824681
B41: Resin_IPA_4.csv | C41: 30.359693 | D41: 0.29679357 | E41: 2.8545825
...

Sheet Averages
A1: Average Tensile Testing Data
A2: Material Type | B2: Chemical Solution | C2: Ultimate Tensile Strength (UTS) [MPa] | D2: Tensile Strain at UTS | E2: Young's Modulus (E) [MPa]
A3: PLA | B3: IPA | C3: 25 ± 2.4 | D3: 0.31 ± 0.025 | E3: 0.44 ± 1.8
B4: Water | C4: 44 ± 0.86 | D4: 0.22 ± 0.010 | E4: 2.9 ± 0.64
B5: Acetone | C5: 45 ± 0.67 | D5: 0.20 ± 0.0090 | E5: 2.8 ± 0.52
B6: Control | C6: 43 ± 0.59 | D6: 0.22 ± 0.0064 | E6: 3.6 ± 1.0
A7: Grey Resin V4 | B7: IPA | C7: 32 ± 1.7 | D7: 0.29 ± 0.036 | E7: 4.1 ± 0.48
B8: Water | C8: 64 ± 0.89 | D8: 0.40 ± 0.022 | E8: 4.1 ± 0.53
B9: Acetone | C9: 60 ± 0.52 | D9: 0.39 ± 0.010 | E9: 5.1 ± 0.56
B10: Control | C10: 64 ± 0.87 | D10: 0.34 ± 0.026 | E10: 3.6 ± 0.31

Sheet Percentage Change
A1: Percentage Change vs. Control
A2: Material Type | B2: Chemical Solution | C2: Tensile Strength | D2: Tensile Strain | E2: Young's Modulus
A3: PLA | B3: IPA | C3: =(Summary!C8-Summary!$C$32)/Summary!$C$32*100 -> -42.392221 | D3: =(Summary!D8-Summary!$D$32)/Summary!$D$32*100 -> 44.681174 | E3: =(Summary!E8-Summary!$E$32)/Summary!$E$32*100 -> -87.936607
B4: Water | C4: =(Summary!C16-Summary!$C$32)/Summary!$C$32*100 -> 3.192829 | D4: =(Summary!D16-Summary!$D$32)/Summary!$D$32*100 -> 0.66598567 | E4: =(Summary!E16-Summary!$E$32)/Summary!$E$32*100 -> -19.673924
B5: Acetone | C5: =(Summary!C24-Summary!$C$32)/Summary!$C$32*100 -> 4.2261937 | D5: =(Summary!D24-Summary!$D$32)/Summary!$D$32*100 -> -7.0474627 | E5: =(Summary!E24-Summary!$E$32)/Summary!$E$32*100 -> -22.2147
A6: Grey Resin V4 | B6: IPA | C6: =(Summary!C43-Summary!$C$67)/(Summary!$C$67)*100 -> -49.534417 | D6: =(Summary!D43-Summary!$D$67)/(Summary!$D$67)*100 -> -15.197406 | E6: =(Summary!E43-Summary!$E$67)/(Summary!$E$67)*100 -> 14.123303
B7: Water | C7: =(Summary!C51-Summary!$C$67)/(Summary!$C$67)*100 -> 0.46593419 | D7: =(Summary!D51-Summary!$D$67)/(Summary!$D$67)*100 -> 19.857679 | E7: =(Summary!E51-Summary!$E$67)/(Summary!$E$67)*100 -> 15.48117
B8: Acetone | C8: =(Summary!C59-Summary!$C$67)/(Summary!$C$67)*100 -> -6.0502806 | D8: =(Summary!D59-Summary!$D$67)/(Summary!$D$67)*100 -> 15.989609 | E8: =(Summary!E59-Summary!$E$67)/(Summary!$E$67)*100 -> 42.206672
